Workbook

Sheet Description
A1: Demand Table
A2: Zone | B2: Shift | C2: Day 1 | D2: Day 2 | E2: Day 3 | F2: Day 4 | G2: Day 5 | H2: Day 6 | I2: Day 7 | J2: Day 8 | K2: Day 9 | L2: Day 10 | M2: Day 11 | N2: Day 12 | O2: Day 13 | P2: Day 14 | Q2: Day 15 | R2: Day 16 | S2: Day 17 | T2: Day 18 | U2: Day 19 | V2: Day 20 | W2: Day 21 | X2: Day 22 | Y2: Day 23 | Z2: Day 24 | AA2: Day 25 | AB2: Day 26 | AC2: Day 27 | AD2: Day 28 | AE2: Day 29 | AF2: Day 30 | AG2: Day 31
A3: Cargo | B3: M | C3: 1 | D3: 1 | E3: 1 | F3: 1 | G3: 1 | H3: 1 | I3: 1 | J3: 1 | K3: 1 | L3: 1 | M3: 1 | N3: 1 | O3: 1 | P3: 1 | Q3: 1 | R3: 1 | S3: 1 | T3: 1 | U3: 1 | V3: 1 | W3: 1 | X3: 1 | Y3: 1 | Z3: 1 | AA3: 1 | AB3: 1 | AC3: 1 | AD3: 1 | AE3: 1 | AF3: 1 | AG3: 1
A4: Cargo | B4: A | C4: 1 | D4: 1 | E4: 1 | F4: 1 | G4: 1 | H4: 1 | I4: 1 | J4: 1 | K4: 1 | L4: 1 | M4: 1 | N4: 1 | O4: 1 | P4: 1 | Q4: 1 | R4: 1 | S4: 1 | T4: 1 | U4: 1 | V4: 1 | W4: 1 | X4: 1 | Y4: 1 | Z4: 1 | AA4: 1 | AB4: 1 | AC4: 1 | AD4: 1 | AE4: 1 | AF4: 1 | AG4: 1
A5: Cargo | B5: N | C5: 1 | D5: 1 | E5: 1 | F5: 1 | G5: 1 | H5: 1 | I5: 1 | J5: 1 | K5: 1 | L5: 1 | M5: 1 | N5: 1 | O5: 1 | P5: 1 | Q5: 1 | R5: 1 | S5: 1 | T5: 1 | U5: 1 | V5: 1 | W5: 1 | X5: 1 | Y5: 1 | Z5: 1 | AA5: 1 | AB5: 1 | AC5: 1 | AD5: 1 | AE5: 1 | AF5: 1 | AG5: 1
A6: Pax | B6: M | C6: 1 | D6: 1 | E6: 1 | F6: 1 | G6: 1 | H6: 1 | I6: 1 | J6: 1 | K6: 1 | L6: 1 | M6: 1 | N6: 1 | O6: 1 | P6: 1 | Q6: 1 | R6: 1 | S6: 1 | T6: 1 | U6: 1 | V6: 1 | W6: 1 | X6: 1 | Y6: 1 | Z6: 1 | AA6: 1 | AB6: 1 | AC6: 1 | AD6: 1 | AE6: 1 | AF6: 1 | AG6: 1
A7: Pax | B7: A | C7: 1 | D7: 1 | E7: 1 | F7: 1 | G7: 1 | H7: 1 | I7: 1 | J7: 1 | K7: 1 | L7: 1 | M7: 1 | N7: 1 | O7: 1 | P7: 1 | Q7: 1 | R7: 1 | S7: 1 | T7: 1 | U7: 1 | V7: 1 | W7: 1 | X7: 1 | Y7: 1 | Z7: 1 | AA7: 1 | AB7: 1 | AC7: 1 | AD7: 1 | AE7: 1 | AF7: 1 | AG7: 1
A8: Pax | B8: N | C8: 1 | D8: 1 | E8: 1 | F8: 1 | G8: 1 | H8: 1 | I8: 1 | J8: 1 | K8: 1 | L8: 1 | M8: 1 | N8: 1 | O8: 1 | P8: 1 | Q8: 1 | R8: 1 | S8: 1 | T8: 1 | U8: 1 | V8: 1 | W8: 1 | X8: 1 | Y8: 1 | Z8: 1 | AA8: 1 | AB8: 1 | AC8: 1 | AD8: 1 | AE8: 1 | AF8: 1 | AG8: 1
A9: Vehicles | B9: M | C9: 1 | D9: 1 | E9: 1 | F9: 1 | G9: 1 | H9: 1 | I9: 1 | J9: 1 | K9: 1 | L9: 1 | M9: 1 | N9: 1 | O9: 1 | P9: 1 | Q9: 1 | R9: 1 | S9: 1 | T9: 1 | U9: 1 | V9: 1 | W9: 1 | X9: 1 | Y9: 1 | Z9: 1 | AA9: 1 | AB9: 1 | AC9: 1 | AD9: 1 | AE9: 1 | AF9: 1 | AG9: 1
A10: Vehicles | B10: A | C10: 1 | D10: 1 | E10: 1 | F10: 1 | G10: 1 | H10: 1 | I10: 1 | J10: 1 | K10: 1 | L10: 1 | M10: 1 | N10: 1 | O10: 1 | P10: 1 | Q10: 1 | R10: 1 | S10: 1 | T10: 1 | U10: 1 | V10: 1 | W10: 1 | X10: 1 | Y10: 1 | Z10: 1 | AA10: 1 | AB10: 1 | AC10: 1 | AD10: 1 | AE10: 1 | AF10: 1 | AG10: 1
A11: Vehicles | B11: N | C11: 1 | D11: 1 | E11: 1 | F11: 1 | G11: 1 | H11: 1 | I11: 1 | J11: 1 | K11: 1 | L11: 1 | M11: 1 | N11: 1 | O11: 1 | P11: 1 | Q11: 1 | R11: 1 | S11: 1 | T11: 1 | U11: 1 | V11: 1 | W11: 1 | X11: 1 | Y11: 1 | Z11: 1 | AA11: 1 | AB11: 1 | AC11: 1 | AD11: 1 | AE11: 1 | AF11: 1 | AG11: 1
A12: Train | B12: M | C12: 1 | D12: 1 | E12: 1 | F12: 1 | G12: 1 | H12: 1 | I12: 1 | J12: 1 | K12: 1 | L12: 1 | M12: 1 | N12: 1 | O12: 1 | P12: 1 | Q12: 1 | R12: 1 | S12: 1 | T12: 1 | U12: 1 | V12: 1 | W12: 1 | X12: 1 | Y12: 1 | Z12: 1 | AA12: 1 | AB12: 1 | AC12: 1 | AD12: 1 | AE12: 1 | AF12: 1 | AG12: 1
A13: Train | B13: A | C13: 1 | D13: 1 | E13: 1 | F13: 1 | G13: 1 | H13: 1 | I13: 1 | J13: 1 | K13: 1 | L13: 1 | M13: 1 | N13: 1 | O13: 1 | P13: 1 | Q13: 1 | R13: 1 | S13: 1 | T13: 1 | U13: 1 | V13: 1 | W13: 1 | X13: 1 | Y13: 1 | Z13: 1 | AA13: 1 | AB13: 1 | AC13: 1 | AD13: 1 | AE13: 1 | AF13: 1 | AG13: 1
A14: Train | B14: N | C14: 1 | D14: 1 | E14: 1 | F14: 1 | G14: 1 | H14: 1 | I14: 1 | J14: 1 | K14: 1 | L14: 1 | M14: 1 | N14: 1 | O14: 1 | P14: 1 | Q14: 1 | R14: 1 | S14: 1 | T14: 1 | U14: 1 | V14: 1 | W14: 1 | X14: 1 | Y14: 1 | Z14: 1 | AA14: 1 | AB14: 1 | AC14: 1 | AD14: 1 | AE14: 1 | AF14: 1 | AG14: 1
A16: In this Test Case, a Transportation company named "Happy Logistics" hires you to develop a small program, using your favourite programming language, to generate Rosters with Zone Assignment for their senior staffs. Below rules have to be guaranteed:
A17: 1 | B17: You are not allowed to change the staffs' Shift Roster in Schedule Table, an example of Shift Roster is shown from Rows 2 through 21 in Schedule Table in "Q1 Answer" sheet.
A18: 2 | B18: Your job is to assign Zone to staffs in Schedule Table. The format is Shift + [Space] + Zone.
A19: 3 | B19: The assignments have to fulfill demand in Demand Table. All demands have to get Passed in Zone Assignment Statistics.
A20: 4 | B20: There are 4 Zones: Cargo, Pax, Vehicles and Train. Once a staffs is assgined to a Zone, the staff has to work at the Zone for the whole month.
A21: 5 | B21: Staffs have to be assigned to Zone by the following Rotation rule: Cargo -> Pax -> Vehicles -> Train. Then restart at Cargo.
B22: Example: if a staff would be assigned to Cargo zone in June, the staff would have to go to Pax zone in July, then Vehicles zone in August, then Train in September. After that the staff could be back to Cargo in October.
A23: Q1.
A24: Use "Q1 Answer" as the template to do your Zone assignment for staffs in Schedule Tab. All cells in Zone Assignment Statistics and Staff Statistics have to Passed.
A26: Q2
A27: This Question uses sheet "Q2 Answer". Given a previous month Zone assignment as shown in Previous Month Schedule Table. Please assign according Zones for staffs in Schedule Tab.
A28: All cells in Zone Assignment Statistics, Staff Statistics and Staff's Zone Rotation Statistics have to Passed.
A30: Importance
A31: 1. Your assignment solutions in "Q1 Answer" and "Q2 Answer" sheets are not allowed to be exactly the same with those of their Passed Examples.
A32: 2. Please submit your source code together with the Answer sheets

Sheet Q1 Answer
A1: Schedule Table
C2: Day 1 | D2: Day 2 | E2: Day 3 | F2: Day 4 | G2: Day 5 | H2: Day 6 | I2: Day 7 | J2: Day 8 | K2: Day 9 | L2: Day 10 | M2: Day 11 | N2: Day 12 | O2: Day 13 | P2: Day 14 | Q2: Day 15 | R2: Day 16 | S2: Day 17 | T2: Day 18 | U2: Day 19 | V2: Day 20 | W2: Day 21 | X2: Day 22 | Y2: Day 23 | Z2: Day 24 | AA2: Day 25 | AB2: Day 26 | AC2: Day 27 | AD2: Day 28 | AE2: Day 29 | AF2: Day 30 | AG2: Day 31
B3: Staff 1 | C3: O | D3: M Pax | E3: M Pax | F3: N Pax | G3: N Pax | H3: O | I3: A Pax | J3: A Pax | K3: O | L3: M Pax | M3: M Pax | N3: N Pax | O3: N Pax | P3: O | Q3: A Pax | R3: A Pax | S3: O | T3: M Pax | U3: M Pax | V3: N Pax | W3: N Pax | X3: O | Y3: A Pax | Z3: A Pax | AA3: O | AB3: M Pax | AC3: M Pax | AD3: N Pax | AE3: N Pax | AF3: O | AG3: A Pax
B4: Staff 2 | C4: O | D4: M Vehicles | E4: M Vehicles | F4: N Vehicles | G4: N Vehicles | H4: O | I4: A Vehicles | J4: A Vehicles | K4: O | L4: M Vehicles | M4: M Vehicles | N4: N Vehicles | O4: N Vehicles | P4: O | Q4: A Vehicles | R4: A Vehicles | S4: O | T4: M Vehicles | U4: M Vehicles | V4: N Vehicles | W4: N Vehicles | X4: O | Y4: A Vehicles | Z4: A Vehicles | AA4: O | AB4: M Vehicles | AC4: M Vehicles | AD4: N Vehicles | AE4: N Vehicles | AF4: O | AG4: A Vehicles
B5: Staff 3 | C5: O | D5: M Cargo | E5: M Cargo | F5: N Cargo | G5: N Cargo | H5: O | I5: A Cargo | J5: A Cargo | K5: O | L5: M Cargo | M5: M Cargo | N5: N Cargo | O5: N Cargo | P5: O | Q5: A Cargo | R5: A Cargo | S5: O | T5: M Cargo | U5: M Cargo | V5: N Cargo | W5: N Cargo | X5: O | Y5: A Cargo | Z5: A Cargo | AA5: O | AB5: M Cargo | AC5: M Cargo | AD5: N Cargo | AE5: N Cargo | AF5: O | AG5: A Cargo
B6: Staff 4 | C6: O | D6: M Train | E6: M Train | F6: N Train | G6: N Train | H6: O | I6: A Train | J6: A Train | K6: O | L6: M Train | M6: M Train | N6: N Train | O6: N Train | P6: O | Q6: A Train | R6: A Train | S6: O | T6: M Train | U6: M Train | V6: N Train | W6: N Train | X6: O | Y6: A Train | Z6: A Train | AA6: O | AB6: M Train | AC6: M Train | AD6: N Train | AE6: N Train | AF6: O | AG6: A Train
B7: Staff 5 | C7: O | D7: M Train | E7: M Train | F7: N Train | G7: N Train | H7: O | I7: A Train | J7: A Train | K7: O | L7: M Train | M7: M Train | N7: N Train | O7: N Train | P7: O | Q7: A Train | R7: A Train | S7: O | T7: M Train | U7: M Train | V7: N Train | W7: N Train | X7: O | Y7: A Train | Z7: A Train | AA7: O | AB7: M Train | AC7: M Train | AD7: N Train | AE7: N Train | AF7: O | AG7: A Train
B8: Staff 6 | C8: A Train | D8: A Train | E8: O | F8: M Train | G8: M Train | H8: N Train | I8: N Train | J8: O | K8: A Train | L8: A Train | M8: O | N8: M Train | O8: M Train | P8: N Train | Q8: N Train | R8: O | S8: A Train | T8: A Train | U8: O | V8: M Train | W8: M Train | X8: N Train | Y8: N Train | Z8: O | AA8: A Train | AB8: A Train | AC8: O | AD8: M Train | AE8: M Train | AF8: N Train | AG8: N Train
B9: Staff 7 | C9: A Vehicles | D9: A Vehicles | E9: O | F9: M Vehicles | G9: M Vehicles | H9: N Vehicles | I9: N Vehicles | J9: O | K9: A Vehicles | L9: A Vehicles | M9: O | N9: M Vehicles | O9: M Vehicles | P9: N Vehicles | Q9: N Vehicles | R9: O | S9: A Vehicles | T9: A Vehicles | U9: O | V9: M Vehicles | W9: M Vehicles | X9: N Vehicles | Y9: N Vehicles | Z9: O | AA9: A Vehicles | AB9: A Vehicles | AC9: O | AD9: M Vehicles | AE9: M Vehicles | AF9: N Vehicles | AG9: N Vehicles
B10: Staff 8 | C10: A Cargo | D10: A Cargo | E10: O | F10: M Cargo | G10: M Cargo | H10: N Cargo | I10: N Cargo | J10: O | K10: A Cargo | L10: A Cargo | M10: O | N10: M Cargo | O10: M Cargo | P10: N Cargo | Q10: N Cargo | R10: O | S10: A Cargo | T10: A Cargo | U10: O | V10: M Cargo | W10: M Cargo | X10: N Cargo | Y10: N Cargo | Z10: O | AA10: A Cargo | AB10: A Cargo | AC10: O | AD10: M Cargo | AE10: M Cargo | AF10: N Cargo | AG10: N Cargo
B11: Staff 9 | C11: A Pax | D11: A Pax | E11: O | F11: M Pax | G11: M Pax | H11: N Pax | I11: N Pax | J11: O | K11: A Pax | L11: A Pax | M11: O | N11: M Pax | O11: M Pax | P11: N Pax | Q11: N Pax | R11: O | S11: A Pax | T11: A Pax | U11: O | V11: M Pax | W11: M Pax | X11: N Pax | Y11: N Pax | Z11: O | AA11: A Pax | AB11: A Pax | AC11: O | AD11: M Pax | AE11: M Pax | AF11: N Pax | AG11: N Pax
B12: Staff 10 | C12: N Cargo | D12: O | E12: A Cargo | F12: A Cargo | G12: O | H12: M Cargo | I12: M Cargo | J12: N Cargo | K12: N Cargo | L12: O | M12: A Cargo | N12: A Cargo | O12: O | P12: M Cargo | Q12: M Cargo | R12: N Cargo | S12: N Cargo | T12: O | U12: A Cargo | V12: A Cargo | W12: O | X12: M Cargo | Y12: M Cargo | Z12: N Cargo | AA12: N Cargo | AB12: O | AC12: A Cargo | AD12: A Cargo | AE12: O | AF12: M Cargo | AG12: M Cargo
B13: Staff 11 | C13: N Train | D13: O | E13: A Train | F13: A Train | G13: O | H13: M Train | I13: M Train | J13: N Train | K13: N Train | L13: O | M13: A Train | N13: A Train | O13: O | P13: M Train | Q13: M Train | R13: N Train | S13: N Train | T13: O | U13: A Train | V13: A Train | W13: O | X13: M Train | Y13: M Train | Z13: N Train | AA13: N Train | AB13: O | AC13: A Train | AD13: A Train | AE13: O | AF13: M Train | AG13: M Train
B14: Staff 12 | C14: N Vehicles | D14: O | E14: A Vehicles | F14: A Vehicles | G14: O | H14: M Vehicles | I14: M Vehicles | J14: N Vehicles | K14: N Vehicles | L14: O | M14: A Vehicles | N14: A Vehicles | O14: O | P14: M Vehicles | Q14: M Vehicles | R14: N Vehicles | S14: N Vehicles | T14: O | U14: A Vehicles | V14: A Vehicles | W14: O | X14: M Vehicles | Y14: M Vehicles | Z14: N Vehicles | AA14: N Vehicles | AB14: O | AC14: A Vehicles | AD14: A Vehicles | AE14: O | AF14: M Vehicles | AG14: M Vehicles
... B21: Staff 19 | C21: M Cargo | D21: N Cargo | E21: N Cargo | F21: O | G21: A Cargo | H21: A Cargo | I21: O | J21: M Cargo | K21: M Cargo | L21: N Cargo | M21: N Cargo | N21: O | O21: A Cargo | P21: A Cargo | Q21: O | R21: M Cargo | S21: M Cargo | T21: N Cargo | U21: N Cargo | V21: O | W21: A Cargo | X21: A Cargo | Y21: O | Z21: M Cargo | AA21: M Cargo | AB21: N Cargo | AC21: N Cargo | AD21: O | AE21: A Cargo | AF21: A Cargo | AG21: O
A23: Zone Assignment Statistics
A24: Zone | B24: Shift | C24: Day 1 | D24: Day 2 | E24: Day 3 | F24: Day 4 | G24: Day 5 | H24: Day 6 | I24: Day 7 | J24: Day 8 | K24: Day 9 | L24: Day 10 | M24: Day 11 | N24: Day 12 | O24: Day 13 | P24: Day 14 | Q24: Day 15 | R24: Day 16 | S24: Day 17 | T24: Day 18 | U24: Day 19 | V24: Day 20 | W24: Day 21 | X24: Day 22 | Y24: Day 23 | Z24: Day 24 | AA24: Day 25 | AB24: Day 26 | AC24: Day 27 | AD24: Day 28 | AE24: Day 29 | AF24: Day 30 | AG24: Day 31
A25: Cargo | B25: M | C25: =IF(COUNTIF(C$3:C$21,$B25&" "&$A25)>=Description!C3,"Passed", "Failed") | D25: =IF(COUNTIF(D$3:D$21,$B25&" "&$A25)>=Description!D3,"Passed", "Failed") | E25: =IF(COUNTIF(E$3:E$21,$B25&" "&$A25)>=Description!E3,"Passed", "Failed") | F25: =IF(COUNTIF(F$3:F$21,$B25&" "&$A25)>=Description!F3,"Passed", "Failed") | G25: =IF(COUNTIF(G$3:G$21,$B25&" "&$A25)>=Description!G3,"Passed", "Failed") | H25: =IF(COUNTIF(H$3:H$21,$B25&" "&$A25)>=Description!H3,"Passed", "Failed") | I25: =IF(COUNTIF(I$3:I$21,$B25&" "&$A25)>=Description!I3,"Passed", "Failed") | J25: =IF(COUNTIF(J$3:J$21,$B25&" "&$A25)>=Description!J3,"Passed", "Failed") | ... AG25: =IF(COUNTIF(AG$3:AG$21,$B25&" "&$A25)>=Description!AG3,"Passed", "Failed")
A26: Cargo | B26: A | C26: =IF(COUNTIF(C$3:C$21,$B26&" "&$A26)>=Description!C4,"Passed", "Failed") | D26: =IF(COUNTIF(D$3:D$21,$B26&" "&$A26)>=Description!D4,"Passed", "Failed") | E26: =IF(COUNTIF(E$3:E$21,$B26&" "&$A26)>=Description!E4,"Passed", "Failed") | F26: =IF(COUNTIF(F$3:F$21,$B26&" "&$A26)>=Description!F4,"Passed", "Failed") | G26: =IF(COUNTIF(G$3:G$21,$B26&" "&$A26)>=Description!G4,"Passed", "Failed") | H26: =IF(COUNTIF(H$3:H$21,$B26&" "&$A26)>=Description!H4,"Passed", "Failed") | I26: =IF(COUNTIF(I$3:I$21,$B26&" "&$A26)>=Description!I4,"Passed", "Failed") | J26: =IF(COUNTIF(J$3:J$21,$B26&" "&$A26)>=Description!J4,"Passed", "Failed") | ... AG26: =IF(COUNTIF(AG$3:AG$21,$B26&" "&$A26)>=Description!AG4,"Passed", "Failed")
A27: Cargo | B27: N | C27: =IF(COUNTIF(C$3:C$21,$B27&" "&$A27)>=Description!C5,"Passed", "Failed") | D27: =IF(COUNTIF(D$3:D$21,$B27&" "&$A27)>=Description!D5,"Passed", "Failed") | E27: =IF(COUNTIF(E$3:E$21,$B27&" "&$A27)>=Description!E5,"Passed", "Failed") | F27: =IF(COUNTIF(F$3:F$21,$B27&" "&$A27)>=Description!F5,"Passed", "Failed") | G27: =IF(COUNTIF(G$3:G$21,$B27&" "&$A27)>=Description!G5,"Passed", "Failed") | H27: =IF(COUNTIF(H$3:H$21,$B27&" "&$A27)>=Description!H5,"Passed", "Failed") | I27: =IF(COUNTIF(I$3:I$21,$B27&" "&$A27)>=Description!I5,"Passed", "Failed") | J27: =IF(COUNTIF(J$3:J$21,$B27&" "&$A27)>=Description!J5,"Passed", "Failed") | ... AG27: =IF(COUNTIF(AG$3:AG$21,$B27&" "&$A27)>=Description!AG5,"Passed", "Failed")
A28: Pax | B28: M | C28: =IF(COUNTIF(C$3:C$21,$B28&" "&$A28)>=Description!C6,"Passed", "Failed") | D28: =IF(COUNTIF(D$3:D$21,$B28&" "&$A28)>=Description!D6,"Passed", "Failed") | E28: =IF(COUNTIF(E$3:E$21,$B28&" "&$A28)>=Description!E6,"Passed", "Failed") | F28: =IF(COUNTIF(F$3:F$21,$B28&" "&$A28)>=Description!F6,"Passed", "Failed") | G28: =IF(COUNTIF(G$3:G$21,$B28&" "&$A28)>=Description!G6,"Passed", "Failed") | H28: =IF(COUNTIF(H$3:H$21,$B28&" "&$A28)>=Description!H6,"Passed", "Failed") | I28: =IF(COUNTIF(I$3:I$21,$B28&" "&$A28)>=Description!I6,"Passed", "Failed") | J28: =IF(COUNTIF(J$3:J$21,$B28&" "&$A28)>=Description!J6,"Passed", "Failed") | ... AG28: =IF(COUNTIF(AG$3:AG$21,$B28&" "&$A28)>=Description!AG6,"Passed", "Failed")
A29: Pax | B29: A | C29: =IF(COUNTIF(C$3:C$21,$B29&" "&$A29)>=Description!C7,"Passed", "Failed") | D29: =IF(COUNTIF(D$3:D$21,$B29&" "&$A29)>=Description!D7,"Passed", "Failed") | E29: =IF(COUNTIF(E$3:E$21,$B29&" "&$A29)>=Description!E7,"Passed", "Failed") | F29: =IF(COUNTIF(F$3:F$21,$B29&" "&$A29)>=Description!F7,"Passed", "Failed") | G29: =IF(COUNTIF(G$3:G$21,$B29&" "&$A29)>=Description!G7,"Passed", "Failed") | H29: =IF(COUNTIF(H$3:H$21,$B29&" "&$A29)>=Description!H7,"Passed", "Failed") | I29: =IF(COUNTIF(I$3:I$21,$B29&" "&$A29)>=Description!I7,"Passed", "Failed") | J29: =IF(COUNTIF(J$3:J$21,$B29&" "&$A29)>=Description!J7,"Passed", "Failed") | ... AG29: =IF(COUNTIF(AG$3:AG$21,$B29&" "&$A29)>=Description!AG7,"Passed", "Failed")
A30: Pax | B30: N | C30: =IF(COUNTIF(C$3:C$21,$B30&" "&$A30)>=Description!C8,"Passed", "Failed") | D30: =IF(COUNTIF(D$3:D$21,$B30&" "&$A30)>=Description!D8,"Passed", "Failed") | E30: =IF(COUNTIF(E$3:E$21,$B30&" "&$A30)>=Description!E8,"Passed", "Failed") | F30: =IF(COUNTIF(F$3:F$21,$B30&" "&$A30)>=Description!F8,"Passed", "Failed") | G30: =IF(COUNTIF(G$3:G$21,$B30&" "&$A30)>=Description!G8,"Passed", "Failed") | H30: =IF(COUNTIF(H$3:H$21,$B30&" "&$A30)>=Description!H8,"Passed", "Failed") | I30: =IF(COUNTIF(I$3:I$21,$B30&" "&$A30)>=Description!I8,"Passed", "Failed") | J30: =IF(COUNTIF(J$3:J$21,$B30&" "&$A30)>=Description!J8,"Passed", "Failed") | ... AG30: =IF(COUNTIF(AG$3:AG$21,$B30&" "&$A30)>=Description!AG8,"Passed", "Failed")
A31: Vehicles | B31: M | C31: =IF(COUNTIF(C$3:C$21,$B31&" "&$A31)>=Description!C9,"Passed", "Failed") | D31: =IF(COUNTIF(D$3:D$21,$B31&" "&$A31)>=Description!D9,"Passed", "Failed") | E31: =IF(COUNTIF(E$3:E$21,$B31&" "&$A31)>=Description!E9,"Passed", "Failed") | F31: =IF(COUNTIF(F$3:F$21,$B31&" "&$A31)>=Description!F9,"Passed", "Failed") | G31: =IF(COUNTIF(G$3:G$21,$B31&" "&$A31)>=Description!G9,"Passed", "Failed") | H31: =IF(COUNTIF(H$3:H$21,$B31&" "&$A31)>=Description!H9,"Passed", "Failed") | I31: =IF(COUNTIF(I$3:I$21,$B31&" "&$A31)>=Description!I9,"Passed", "Failed") | J31: =IF(COUNTIF(J$3:J$21,$B31&" "&$A31)>=Description!J9,"Passed", "Failed") | ... AG31: =IF(COUNTIF(AG$3:AG$21,$B31&" "&$A31)>=Description!AG9,"Passed", "Failed")
A32: Vehicles | B32: A | C32: =IF(COUNTIF(C$3:C$21,$B32&" "&$A32)>=Description!C10,"Passed", "Failed") | D32: =IF(COUNTIF(D$3:D$21,$B32&" "&$A32)>=Description!D10,"Passed", "Failed") | E32: =IF(COUNTIF(E$3:E$21,$B32&" "&$A32)>=Description!E10,"Passed", "Failed") | F32: =IF(COUNTIF(F$3:F$21,$B32&" "&$A32)>=Description!F10,"Passed", "Failed") | G32: =IF(COUNTIF(G$3:G$21,$B32&" "&$A32)>=Description!G10,"Passed", "Failed") | H32: =IF(COUNTIF(H$3:H$21,$B32&" "&$A32)>=Description!H10,"Passed", "Failed") | I32: =IF(COUNTIF(I$3:I$21,$B32&" "&$A32)>=Description!I10,"Passed", "Failed") | J32: =IF(COUNTIF(J$3:J$21,$B32&" "&$A32)>=Description!J10,"Passed", "Failed") | ... AG32: =IF(COUNTIF(AG$3:AG$21,$B32&" "&$A32)>=Description!AG10,"Passed", "Failed")
A33: Vehicles | B33: N | C33: =IF(COUNTIF(C$3:C$21,$B33&" "&$A33)>=Description!C11,"Passed", "Failed") | D33: =IF(COUNTIF(D$3:D$21,$B33&" "&$A33)>=Description!D11,"Passed", "Failed") | E33: =IF(COUNTIF(E$3:E$21,$B33&" "&$A33)>=Description!E11,"Passed", "Failed") | F33: =IF(COUNTIF(F$3:F$21,$B33&" "&$A33)>=Description!F11,"Passed", "Failed") | G33: =IF(COUNTIF(G$3:G$21,$B33&" "&$A33)>=Description!G11,"Passed", "Failed") | H33: =IF(COUNTIF(H$3:H$21,$B33&" "&$A33)>=Description!H11,"Passed", "Failed") | I33: =IF(COUNTIF(I$3:I$21,$B33&" "&$A33)>=Description!I11,"Passed", "Failed") | J33: =IF(COUNTIF(J$3:J$21,$B33&" "&$A33)>=Description!J11,"Passed", "Failed") | ... AG33: =IF(COUNTIF(AG$3:AG$21,$B33&" "&$A33)>=Description!AG11,"Passed", "Failed")
A34: Train | B34: M | C34: =IF(COUNTIF(C$3:C$21,$B34&" "&$A34)>=Description!C12,"Passed", "Failed") | D34: =IF(COUNTIF(D$3:D$21,$B34&" "&$A34)>=Description!D12,"Passed", "Failed") | E34: =IF(COUNTIF(E$3:E$21,$B34&" "&$A34)>=Description!E12,"Passed", "Failed") | F34: =IF(COUNTIF(F$3:F$21,$B34&" "&$A34)>=Description!F12,"Passed", "Failed") | G34: =IF(COUNTIF(G$3:G$21,$B34&" "&$A34)>=Description!G12,"Passed", "Failed") | H34: =IF(COUNTIF(H$3:H$21,$B34&" "&$A34)>=Description!H12,"Passed", "Failed") | I34: =IF(COUNTIF(I$3:I$21,$B34&" "&$A34)>=Description!I12,"Passed", "Failed") | J34: =IF(COUNTIF(J$3:J$21,$B34&" "&$A34)>=Description!J12,"Passed", "Failed") | ... AG34: =IF(COUNTIF(AG$3:AG$21,$B34&" "&$A34)>=Description!AG12,"Passed", "Failed")
A35: Train | B35: A | C35: =IF(COUNTIF(C$3:C$21,$B35&" "&$A35)>=Description!C13,"Passed", "Failed") | D35: =IF(COUNTIF(D$3:D$21,$B35&" "&$A35)>=Description!D13,"Passed", "Failed") | E35: =IF(COUNTIF(E$3:E$21,$B35&" "&$A35)>=Description!E13,"Passed", "Failed") | F35: =IF(COUNTIF(F$3:F$21,$B35&" "&$A35)>=Description!F13,"Passed", "Failed") | G35: =IF(COUNTIF(G$3:G$21,$B35&" "&$A35)>=Description!G13,"Passed", "Failed") | H35: =IF(COUNTIF(H$3:H$21,$B35&" "&$A35)>=Description!H13,"Passed", "Failed") | I35: =IF(COUNTIF(I$3:I$21,$B35&" "&$A35)>=Description!I13,"Passed", "Failed") | J35: =IF(COUNTIF(J$3:J$21,$B35&" "&$A35)>=Description!J13,"Passed", "Failed") | ... AG35: =IF(COUNTIF(AG$3:AG$21,$B35&" "&$A35)>=Description!AG13,"Passed", "Failed")
A36: Train | B36: N | C36: =IF(COUNTIF(C$3:C$21,$B36&" "&$A36)>=Description!C14,"Passed", "Failed") | D36: =IF(COUNTIF(D$3:D$21,$B36&" "&$A36)>=Description!D14,"Passed", "Failed") | E36: =IF(COUNTIF(E$3:E$21,$B36&" "&$A36)>=Description!E14,"Passed", "Failed") | F36: =IF(COUNTIF(F$3:F$21,$B36&" "&$A36)>=Description!F14,"Passed", "Failed") | G36: =IF(COUNTIF(G$3:G$21,$B36&" "&$A36)>=Description!G14,"Passed", "Failed") | H36: =IF(COUNTIF(H$3:H$21,$B36&" "&$A36)>=Description!H14,"Passed", "Failed") | I36: =IF(COUNTIF(I$3:I$21,$B36&" "&$A36)>=Description!I14,"Passed", "Failed") | J36: =IF(COUNTIF(J$3:J$21,$B36&" "&$A36)>=Description!J14,"Passed", "Failed") | ... AG36: =IF(COUNTIF(AG$3:AG$21,$B36&" "&$A36)>=Description!AG14,"Passed", "Failed")
A38: Staff Statistics
A39: Staff 1 | B39: {=IFERROR(IF(ROUNDUP(SUMPRODUCT(1/COUNTIF(C39:AG39,C39:AG39)),0)<=2, "Passed", "Failed"),"Failed")} | C39: =IF(LEN(C3)=1,"",RIGHT(C3,LEN(C3)-2)) | D39: =IF(LEN(D3)=1,"",RIGHT(D3,LEN(D3)-2)) | E39: =IF(LEN(E3)=1,"",RIGHT(E3,LEN(E3)-2)) | F39: =IF(LEN(F3)=1,"",RIGHT(F3,LEN(F3)-2)) | G39: =IF(LEN(G3)=1,"",RIGHT(G3,LEN(G3)-2)) | H39: =IF(LEN(H3)=1,"",RIGHT(H3,LEN(H3)-2)) | I39: =IF(LEN(I3)=1,"",RIGHT(I3,LEN(I3)-2)) | J39: =IF(LEN(J3)=1,"",RIGHT(J3,LEN(J3)-2)) | ... AG39: =IF(LEN(AG3)=1,"",RIGHT(AG3,LEN(AG3)-2))
A40: Staff 2 | B40: {=IFERROR(IF(ROUNDUP(SUMPRODUCT(1/COUNTIF(C40:AG40,C40:AG40)),0)<=2, "Passed", "Failed"),"Failed")} | C40: =IF(LEN(C4)=1,"",RIGHT(C4,LEN(C4)-2)) | D40: =IF(LEN(D4)=1,"",RIGHT(D4,LEN(D4)-2)) | E40: =IF(LEN(E4)=1,"",RIGHT(E4,LEN(E4)-2)) | F40: =IF(LEN(F4)=1,"",RIGHT(F4,LEN(F4)-2)) | G40: =IF(LEN(G4)=1,"",RIGHT(G4,LEN(G4)-2)) | H40: =IF(LEN(H4)=1,"",RIGHT(H4,LEN(H4)-2)) | I40: =IF(LEN(I4)=1,"",RIGHT(I4,LEN(I4)-2)) | J40: =IF(LEN(J4)=1,"",RIGHT(J4,LEN(J4)-2)) | ... AG40: =IF(LEN(AG4)=1,"",RIGHT(AG4,LEN(AG4)-2))
A41: Staff 3 | B41: {=IFERROR(IF(ROUNDUP(SUMPRODUCT(1/COUNTIF(C41:AG41,C41:AG41)),0)<=2, "Passed", "Failed"),"Failed")} | C41: =IF(LEN(C5)=1,"",RIGHT(C5,LEN(C5)-2)) | D41: =IF(LEN(D5)=1,"",RIGHT(D5,LEN(D5)-2)) | E41: =IF(LEN(E5)=1,"",RIGHT(E5,LEN(E5)-2)) | F41: =IF(LEN(F5)=1,"",RIGHT(F5,LEN(F5)-2)) | G41: =IF(LEN(G5)=1,"",RIGHT(G5,LEN(G5)-2)) | H41: =IF(LEN(H5)=1,"",RIGHT(H5,LEN(H5)-2)) | I41: =IF(LEN(I5)=1,"",RIGHT(I5,LEN(I5)-2)) | J41: =IF(LEN(J5)=1,"",RIGHT(J5,LEN(J5)-2)) | ... AG41: =IF(LEN(AG5)=1,"",RIGHT(AG5,LEN(AG5)-2))
A42: Staff 4 | B42: {=IFERROR(IF(ROUNDUP(SUMPRODUCT(1/COUNTIF(C42:AG42,C42:AG42)),0)<=2, "Passed", "Failed"),"Failed")} | C42: =IF(LEN(C6)=1,"",RIGHT(C6,LEN(C6)-2)) | D42: =IF(LEN(D6)=1,"",RIGHT(D6,LEN(D6)-2)) | E42: =IF(LEN(E6)=1,"",RIGHT(E6,LEN(E6)-2)) | F42: =IF(LEN(F6)=1,"",RIGHT(F6,LEN(F6)-2)) | G42: =IF(LEN(G6)=1,"",RIGHT(G6,LEN(G6)-2)) | H42: =IF(LEN(H6)=1,"",RIGHT(H6,LEN(H6)-2)) | I42: =IF(LEN(I6)=1,"",RIGHT(I6,LEN(I6)-2)) | J42: =IF(LEN(J6)=1,"",RIGHT(J6,LEN(J6)-2)) | ... AG42: =IF(LEN(AG6)=1,"",RIGHT(AG6,LEN(AG6)-2))
A43: Staff 5 | B43: {=IFERROR(IF(ROUNDUP(SUMPRODUCT(1/COUNTIF(C43:AG43,C43:AG43)),0)<=2, "Passed", "Failed"),"Failed")} | C43: =IF(LEN(C7)=1,"",RIGHT(C7,LEN(C7)-2)) | D43: =IF(LEN(D7)=1,"",RIGHT(D7,LEN(D7)-2)) | E43: =IF(LEN(E7)=1,"",RIGHT(E7,LEN(E7)-2)) | F43: =IF(LEN(F7)=1,"",RIGHT(F7,LEN(F7)-2)) | G43: =IF(LEN(G7)=1,"",RIGHT(G7,LEN(G7)-2)) | H43: =IF(LEN(H7)=1,"",RIGHT(H7,LEN(H7)-2)) | I43: =IF(LEN(I7)=1,"",RIGHT(I7,LEN(I7)-2)) | J43: =IF(LEN(J7)=1,"",RIGHT(J7,LEN(J7)-2)) | ... AG43: =IF(LEN(AG7)=1,"",RIGHT(AG7,LEN(AG7)-2))
A44: Staff 6 | B44: {=IFERROR(IF(ROUNDUP(SUMPRODUCT(1/COUNTIF(C44:AG44,C44:AG44)),0)<=2, "Passed", "Failed"),"Failed")} | C44: =IF(LEN(C8)=1,"",RIGHT(C8,LEN(C8)-2)) | D44: =IF(LEN(D8)=1,"",RIGHT(D8,LEN(D8)-2)) | E44: =IF(LEN(E8)=1,"",RIGHT(E8,LEN(E8)-2)) | F44: =IF(LEN(F8)=1,"",RIGHT(F8,LEN(F8)-2)) | G44: =IF(LEN(G8)=1,"",RIGHT(G8,LEN(G8)-2)) | H44: =IF(LEN(H8)=1,"",RIGHT(H8,LEN(H8)-2)) | I44: =IF(LEN(I8)=1,"",RIGHT(I8,LEN(I8)-2)) | J44: =IF(LEN(J8)=1,"",RIGHT(J8,LEN(J8)-2)) | ... AG44: =IF(LEN(AG8)=1,"",RIGHT(AG8,LEN(AG8)-2))
A45: Staff 7 | B45: {=IFERROR(IF(ROUNDUP(SUMPRODUCT(1/COUNTIF(C45:AG45,C45:AG45)),0)<=2, "Passed", "Failed"),"Failed")} | C45: =IF(LEN(C9)=1,"",RIGHT(C9,LEN(C9)-2)) | D45: =IF(LEN(D9)=1,"",RIGHT(D9,LEN(D9)-2)) | E45: =IF(LEN(E9)=1,"",RIGHT(E9,LEN(E9)-2)) | F45: =IF(LEN(F9)=1,"",RIGHT(F9,LEN(F9)-2)) | G45: =IF(LEN(G9)=1,"",RIGHT(G9,LEN(G9)-2)) | H45: =IF(LEN(H9)=1,"",RIGHT(H9,LEN(H9)-2)) | I45: =IF(LEN(I9)=1,"",RIGHT(I9,LEN(I9)-2)) | J45: =IF(LEN(J9)=1,"",RIGHT(J9,LEN(J9)-2)) | ... AG45: =IF(LEN(AG9)=1,"",RIGHT(AG9,LEN(AG9)-2))
A46: Staff 8 | B46: {=IFERROR(IF(ROUNDUP(SUMPRODUCT(1/COUNTIF(C46:AG46,C46:AG46)),0)<=2, "Passed", "Failed"),"Failed")} | C46: =IF(LEN(C10)=1,"",RIGHT(C10,LEN(C10)-2)) | D46: =IF(LEN(D10)=1,"",RIGHT(D10,LEN(D10)-2)) | E46: =IF(LEN(E10)=1,"",RIGHT(E10,LEN(E10)-2)) | F46: =IF(LEN(F10)=1,"",RIGHT(F10,LEN(F10)-2)) | G46: =IF(LEN(G10)=1,"",RIGHT(G10,LEN(G10)-2)) | H46: =IF(LEN(H10)=1,"",RIGHT(H10,LEN(H10)-2)) | I46: =IF(LEN(I10)=1,"",RIGHT(I10,LEN(I10)-2)) | J46: =IF(LEN(J10)=1,"",RIGHT(J10,LEN(J10)-2)) | ... AG46: =IF(LEN(AG10)=1,"",RIGHT(AG10,LEN(AG10)-2))
A47: Staff 9 | B47: {=IFERROR(IF(ROUNDUP(SUMPRODUCT(1/COUNTIF(C47:AG47,C47:AG47)),0)<=2, "Passed", "Failed"),"Failed")} | C47: =IF(LEN(C11)=1,"",RIGHT(C11,LEN(C11)-2)) | D47: =IF(LEN(D11)=1,"",RIGHT(D11,LEN(D11)-2)) | E47: =IF(LEN(E11)=1,"",RIGHT(E11,LEN(E11)-2)) | F47: =IF(LEN(F11)=1,"",RIGHT(F11,LEN(F11)-2)) | G47: =IF(LEN(G11)=1,"",RIGHT(G11,LEN(G11)-2)) | H47: =IF(LEN(H11)=1,"",RIGHT(H11,LEN(H11)-2)) | I47: =IF(LEN(I11)=1,"",RIGHT(I11,LEN(I11)-2)) | J47: =IF(LEN(J11)=1,"",RIGHT(J11,LEN(J11)-2)) | ... AG47: =IF(LEN(AG11)=1,"",RIGHT(AG11,LEN(AG11)-2))
A48: Staff 10 | B48: {=IFERROR(IF(ROUNDUP(SUMPRODUCT(1/COUNTIF(C48:AG48,C48:AG48)),0)<=2, "Passed", "Failed"),"Failed")} | C48: =IF(LEN(C12)=1,"",RIGHT(C12,LEN(C12)-2)) | D48: =IF(LEN(D12)=1,"",RIGHT(D12,LEN(D12)-2)) | E48: =IF(LEN(E12)=1,"",RIGHT(E12,LEN(E12)-2)) | F48: =IF(LEN(F12)=1,"",RIGHT(F12,LEN(F12)-2)) | G48: =IF(LEN(G12)=1,"",RIGHT(G12,LEN(G12)-2)) | H48: =IF(LEN(H12)=1,"",RIGHT(H12,LEN(H12)-2)) | I48: =IF(LEN(I12)=1,"",RIGHT(I12,LEN(I12)-2)) | J48: =IF(LEN(J12)=1,"",RIGHT(J12,LEN(J12)-2)) | ... AG48: =IF(LEN(AG12)=1,"",RIGHT(AG12,LEN(AG12)-2))
...

Sheet Q2 Answer
A1: Schedule Table
C2: Day 1 | D2: Day 2 | E2: Day 3 | F2: Day 4 | G2: Day 5 | H2: Day 6 | I2: Day 7 | J2: Day 8 | K2: Day 9 | L2: Day 10 | M2: Day 11 | N2: Day 12 | O2: Day 13 | P2: Day 14 | Q2: Day 15 | R2: Day 16 | S2: Day 17 | T2: Day 18 | U2: Day 19 | V2: Day 20 | W2: Day 21 | X2: Day 22 | Y2: Day 23 | Z2: Day 24 | AA2: Day 25 | AB2: Day 26 | AC2: Day 27 | AD2: Day 28 | AE2: Day 29 | AF2: Day 30 | AG2: Day 31
B3: Staff 1 | C3: O | D3: M Train | E3: M Train | F3: N Train | G3: N Train | H3: O | I3: A Train | J3: A Train | K3: O | L3: M Train | M3: M Train | N3: N Train | O3: N Train | P3: O | Q3: A Train | R3: A Train | S3: O | T3: M Train | U3: M Train | V3: N Train | W3: N Train | X3: O | Y3: A Train | Z3: A Train | AA3: O | AB3: M Train | AC3: M Train | AD3: N Train | AE3: N Train | AF3: O | AG3: A Train
B4: Staff 2 | C4: O | D4: M Vehicles | E4: M Vehicles | F4: N Vehicles | G4: N Vehicles | H4: O | I4: A Vehicles | J4: A Vehicles | K4: O | L4: M Vehicles | M4: M Vehicles | N4: N Vehicles | O4: N Vehicles | P4: O | Q4: A Vehicles | R4: A Vehicles | S4: O | T4: M Vehicles | U4: M Vehicles | V4: N Vehicles | W4: N Vehicles | X4: O | Y4: A Vehicles | Z4: A Vehicles | AA4: O | AB4: M Vehicles | AC4: M Vehicles | AD4: N Vehicles | AE4: N Vehicles | AF4: O | AG4: A Vehicles
B5: Staff 3 | C5: O | D5: M Pax | E5: M Pax | F5: N Pax | G5: N Pax | H5: O | I5: A Pax | J5: A Pax | K5: O | L5: M Pax | M5: M Pax | N5: N Pax | O5: N Pax | P5: O | Q5: A Pax | R5: A Pax | S5: O | T5: M Pax | U5: M Pax | V5: N Pax | W5: N Pax | X5: O | Y5: A Pax | Z5: A Pax | AA5: O | AB5: M Pax | AC5: M Pax | AD5: N Pax | AE5: N Pax | AF5: O | AG5: A Pax
B6: Staff 4 | C6: O | D6: M Train | E6: M Train | F6: N Train | G6: N Train | H6: O | I6: A Train | J6: A Train | K6: O | L6: M Train | M6: M Train | N6: N Train | O6: N Train | P6: O | Q6: A Train | R6: A Train | S6: O | T6: M Train | U6: M Train | V6: N Train | W6: N Train | X6: O | Y6: A Train | Z6: A Train | AA6: O | AB6: M Train | AC6: M Train | AD6: N Train | AE6: N Train | AF6: O | AG6: A Train
B7: Staff 5 | C7: O | D7: M Cargo | E7: M Cargo | F7: N Cargo | G7: N Cargo | H7: O | I7: A Cargo | J7: A Cargo | K7: O | L7: M Cargo | M7: M Cargo | N7: N Cargo | O7: N Cargo | P7: O | Q7: A Cargo | R7: A Cargo | S7: O | T7: M Cargo | U7: M Cargo | V7: N Cargo | W7: N Cargo | X7: O | Y7: A Cargo | Z7: A Cargo | AA7: O | AB7: M Cargo | AC7: M Cargo | AD7: N Cargo | AE7: N Cargo | AF7: O | AG7: A Cargo
B8: Staff 6 | C8: A Train | D8: A Train | E8: O | F8: M Train | G8: M Train | H8: N Train | I8: N Train | J8: O | K8: A Train | L8: A Train | M8: O | N8: M Train | O8: M Train | P8: N Train | Q8: N Train | R8: O | S8: A Train | T8: A Train | U8: O | V8: M Train | W8: M Train | X8: N Train | Y8: N Train | Z8: O | AA8: A Train | AB8: A Train | AC8: O | AD8: M Train | AE8: M Train | AF8: N Train | AG8: N Train
B9: Staff 7 | C9: A Cargo | D9: A Cargo | E9: O | F9: M Cargo | G9: M Cargo | H9: N Cargo | I9: N Cargo | J9: O | K9: A Cargo | L9: A Cargo | M9: O | N9: M Cargo | O9: M Cargo | P9: N Cargo | Q9: N Cargo | R9: O | S9: A Cargo | T9: A Cargo | U9: O | V9: M Cargo | W9: M Cargo | X9: N Cargo | Y9: N Cargo | Z9: O | AA9: A Cargo | AB9: A Cargo | AC9: O | AD9: M Cargo | AE9: M Cargo | AF9: N Cargo | AG9: N Cargo
B10: Staff 8 | C10: A Vehicles | D10: A Vehicles | E10: O | F10: M Vehicles | G10: M Vehicles | H10: N Vehicles | I10: N Vehicles | J10: O | K10: A Vehicles | L10: A Vehicles | M10: O | N10: M Vehicles | O10: M Vehicles | P10: N Vehicles | Q10: N Vehicles | R10: O | S10: A Vehicles | T10: A Vehicles | U10: O | V10: M Vehicles | W10: M Vehicles | X10: N Vehicles | Y10: N Vehicles | Z10: O | AA10: A Vehicles | AB10: A Vehicles | AC10: O | AD10: M Vehicles | AE10: M Vehicles | AF10: N Vehicles | AG10: N Vehicles
B11: Staff 9 | C11: A Pax | D11: A Pax | E11: O | F11: M Pax | G11: M Pax | H11: N Pax | I11: N Pax | J11: O | K11: A Pax | L11: A Pax | M11: O | N11: M Pax | O11: M Pax | P11: N Pax | Q11: N Pax | R11: O | S11: A Pax | T11: A Pax | U11: O | V11: M Pax | W11: M Pax | X11: N Pax | Y11: N Pax | Z11: O | AA11: A Pax | AB11: A Pax | AC11: O | AD11: M Pax | AE11: M Pax | AF11: N Pax | AG11: N Pax
B12: Staff 10 | C12: N Train | D12: O | E12: A Train | F12: A Train | G12: O | H12: M Train | I12: M Train | J12: N Train | K12: N Train | L12: O | M12: A Train | N12: A Train | O12: O | P12: M Train | Q12: M Train | R12: N Train | S12: N Train | T12: O | U12: A Train | V12: A Train | W12: O | X12: M Train | Y12: M Train | Z12: N Train | AA12: N Train | AB12: O | AC12: A Train | AD12: A Train | AE12: O | AF12: M Train | AG12: M Train
B13: Staff 11 | C13: N Cargo | D13: O | E13: A Cargo | F13: A Cargo | G13: O | H13: M Cargo | I13: M Cargo | J13: N Cargo | K13: N Cargo | L13: O | M13: A Cargo | N13: A Cargo | O13: O | P13: M Cargo | Q13: M Cargo | R13: N Cargo | S13: N Cargo | T13: O | U13: A Cargo | V13: A Cargo | W13: O | X13: M Cargo | Y13: M Cargo | Z13: N Cargo | AA13: N Cargo | AB13: O | AC13: A Cargo | AD13: A Cargo | AE13: O | AF13: M Cargo | AG13: M Cargo
B14: Staff 12 | C14: N Vehicles | D14: O | E14: A Vehicles | F14: A Vehicles | G14: O | H14: M Vehicles | I14: M Vehicles | J14: N Vehicles | K14: N Vehicles | L14: O | M14: A Vehicles | N14: A Vehicles | O14: O | P14: M Vehicles | Q14: M Vehicles | R14: N Vehicles | S14: N Vehicles | T14: O | U14: A Vehicles | V14: A Vehicles | W14: O | X14: M Vehicles | Y14: M Vehicles | Z14: N Vehicles | AA14: N Vehicles | AB14: O | AC14: A Vehicles | AD14: A Vehicles | AE14: O | AF14: M Vehicles | AG14: M Vehicles
... B21: Staff 19 | C21: M Train | D21: N Train | E21: N Train | F21: O | G21: A Train | H21: A Train | I21: O | J21: M Train | K21: M Train | L21: N Train | M21: N Train | N21: O | O21: A Train | P21: A Train | Q21: O | R21: M Train | S21: M Train | T21: N Train | U21: N Train | V21: O | W21: A Train | X21: A Train | Y21: O | Z21: M Train | AA21: M Train | AB21: N Train | AC21: N Train | AD21: O | AE21: A Train | AF21: A Train | AG21: O
A23: Previous Month Schedule Table
C24: Day 1 | D24: Day 2 | E24: Day 3 | F24: Day 4 | G24: Day 5 | H24: Day 6 | I24: Day 7 | J24: Day 8 | K24: Day 9 | L24: Day 10 | M24: Day 11 | N24: Day 12 | O24: Day 13 | P24: Day 14 | Q24: Day 15 | R24: Day 16 | S24: Day 17 | T24: Day 18 | U24: Day 19 | V24: Day 20 | W24: Day 21 | X24: Day 22 | Y24: Day 23 | Z24: Day 24 | AA24: Day 25 | AB24: Day 26 | AC24: Day 27 | AD24: Day 28 | AE24: Day 29 | AF24: Day 30
B25: Staff 1 | C25: M Vehicles | D25: N Vehicles | E25: N Vehicles | F25: O | G25: A Vehicles | H25: A Vehicles | I25: O | J25: M Vehicles | K25: M Vehicles | L25: N Vehicles | M25: N Vehicles | N25: O | O25: A Vehicles | P25: A Vehicles | Q25: O | R25: M Vehicles | S25: M Vehicles | T25: N Vehicles | U25: N Vehicles | V25: O | W25: A Vehicles | X25: A Vehicles | Y25: O | Z25: M Vehicles | AA25: M Vehicles | AB25: N Vehicles | AC25: N Vehicles | AD25: O | AE25: A Vehicles | AF25: A Vehicles
B26: Staff 2 | C26: M Pax | D26: N Pax | E26: N Pax | F26: O | G26: A Pax | H26: A Pax | I26: O | J26: M Pax | K26: M Pax | L26: N Pax | M26: N Pax | N26: O | O26: A Pax | P26: A Pax | Q26: O | R26: M Pax | S26: M Pax | T26: N Pax | U26: N Pax | V26: O | W26: A Pax | X26: A Pax | Y26: O | Z26: M Pax | AA26: M Pax | AB26: N Pax | AC26: N Pax | AD26: O | AE26: A Pax | AF26: A Pax
B27: Staff 3 | C27: M Cargo | D27: N Cargo | E27: N Cargo | F27: O | G27: A Cargo | H27: A Cargo | I27: O | J27: M Cargo | K27: M Cargo | L27: N Cargo | M27: N Cargo | N27: O | O27: A Cargo | P27: A Cargo | Q27: O | R27: M Cargo | S27: M Cargo | T27: N Cargo | U27: N Cargo | V27: O | W27: A Cargo | X27: A Cargo | Y27: O | Z27: M Cargo | AA27: M Cargo | AB27: N Cargo | AC27: N Cargo | AD27: O | AE27: A Cargo | AF27: A Cargo
B28: Staff 4 | C28: M Vehicles | D28: N Vehicles | E28: N Vehicles | F28: O | G28: A Vehicles | H28: A Vehicles | I28: O | J28: M Vehicles | K28: M Vehicles | L28: N Vehicles | M28: N Vehicles | N28: O | O28: A Vehicles | P28: A Vehicles | Q28: O | R28: M Vehicles | S28: M Vehicles | T28: N Vehicles | U28: N Vehicles | V28: O | W28: A Vehicles | X28: A Vehicles | Y28: O | Z28: M Vehicles | AA28: M Vehicles | AB28: N Vehicles | AC28: N Vehicles | AD28: O | AE28: A Vehicles | AF28: A Vehicles
B29: Staff 5 | C29: M Train | D29: N Train | E29: N Train | F29: O | G29: A Train | H29: A Train | I29: O | J29: M Train | K29: M Train | L29: N Train | M29: N Train | N29: O | O29: A Train | P29: A Train | Q29: O | R29: M Train | S29: M Train | T29: N Train | U29: N Train | V29: O | W29: A Train | X29: A Train | Y29: O | Z29: M Train | AA29: M Train | AB29: N Train | AC29: N Train | AD29: O | AE29: A Train | AF29: A Train
B30: Staff 6 | C30: O | D30: M Vehicles | E30: M Vehicles | F30: N Vehicles | G30: N Vehicles | H30: O | I30: A Vehicles | J30: A Vehicles | K30: O | L30: M Vehicles | M30: M Vehicles | N30: N Vehicles | O30: N Vehicles | P30: O | Q30: A Vehicles | R30: A Vehicles | S30: O | T30: M Vehicles | U30: M Vehicles | V30: N Vehicles | W30: N Vehicles | X30: O | Y30: A Vehicles | Z30: A Vehicles | AA30: O | AB30: M Vehicles | AC30: M Vehicles | AD30: N Vehicles | AE30: N Vehicles | AF30: O
B31: Staff 7 | C31: O | D31: M Train | E31: M Train | F31: N Train | G31: N Train | H31: O | I31: A Train | J31: A Train | K31: O | L31: M Train | M31: M Train | N31: N Train | O31: N Train | P31: O | Q31: A Train | R31: A Train | S31: O | T31: M Train | U31: M Train | V31: N Train | W31: N Train | X31: O | Y31: A Train | Z31: A Train | AA31: O | AB31: M Train | AC31: M Train | AD31: N Train | AE31: N Train | AF31: O
B32: Staff 8 | C32: O | D32: M Pax | E32: M Pax | F32: N Pax | G32: N Pax | H32: O | I32: A Pax | J32: A Pax | K32: O | L32: M Pax | M32: M Pax | N32: N Pax | O32: N Pax | P32: O | Q32: A Pax | R32: A Pax | S32: O | T32: M Pax | U32: M Pax | V32: N Pax | W32: N Pax | X32: O | Y32: A Pax | Z32: A Pax | AA32: O | AB32: M Pax | AC32: M Pax | AD32: N Pax | AE32: N Pax | AF32: O
B33: Staff 9 | C33: O | D33: M Cargo | E33: M Cargo | F33: N Cargo | G33: N Cargo | H33: O | I33: A Cargo | J33: A Cargo | K33: O | L33: M Cargo | M33: M Cargo | N33: N Cargo | O33: N Cargo | P33: O | Q33: A Cargo | R33: A Cargo | S33: O | T33: M Cargo | U33: M Cargo | V33: N Cargo | W33: N Cargo | X33: O | Y33: A Cargo | Z33: A Cargo | AA33: O | AB33: M Cargo | AC33: M Cargo | AD33: N Cargo | AE33: N Cargo | AF33: O
B34: Staff 10 | C34: A Vehicles | D34: A Vehicles | E34: O | F34: M Vehicles | G34: M Vehicles | H34: N Vehicles | I34: N Vehicles | J34: O | K34: A Vehicles | L34: A Vehicles | M34: O | N34: M Vehicles | O34: M Vehicles | P34: N Vehicles | Q34: N Vehicles | R34: O | S34: A Vehicles | T34: A Vehicles | U34: O | V34: M Vehicles | W34: M Vehicles | X34: N Vehicles | Y34: N Vehicles | Z34: O | AA34: A Vehicles | AB34: A Vehicles | AC34: O | AD34: M Vehicles | AE34: M Vehicles | AF34: N Vehicles
B35: Staff 11 | C35: A Train | D35: A Train | E35: O | F35: M Train | G35: M Train | H35: N Train | I35: N Train | J35: O | K35: A Train | L35: A Train | M35: O | N35: M Train | O35: M Train | P35: N Train | Q35: N Train | R35: O | S35: A Train | T35: A Train | U35: O | V35: M Train | W35: M Train | X35: N Train | Y35: N Train | Z35: O | AA35: A Train | AB35: A Train | AC35: O | AD35: M Train | AE35: M Train | AF35: N Train
B36: Staff 12 | C36: A Pax | D36: A Pax | E36: O | F36: M Pax | G36: M Pax | H36: N Pax | I36: N Pax | J36: O | K36: A Pax | L36: A Pax | M36: O | N36: M Pax | O36: M Pax | P36: N Pax | Q36: N Pax | R36: O | S36: A Pax | T36: A Pax | U36: O | V36: M Pax | W36: M Pax | X36: N Pax | Y36: N Pax | Z36: O | AA36: A Pax | AB36: A Pax | AC36: O | AD36: M Pax | AE36: M Pax | AF36: N Pax
... B43: Staff 19 | C43: N Vehicles | D43: O | E43: A Vehicles | F43: A Vehicles | G43: O | H43: M Vehicles | I43: M Vehicles | J43: N Vehicles | K43: N Vehicles | L43: O | M43: A Vehicles | N43: A Vehicles | O43: O | P43: M Vehicles | Q43: M Vehicles | R43: N Vehicles | S43: N Vehicles | T43: O | U43: A Vehicles | V43: A Vehicles | W43: O | X43: M Vehicles | Y43: M Vehicles | Z43: N Vehicles | AA43: N Vehicles | AB43: O | AC43: A Vehicles | AD43: A Vehicles | AE43: O | AF43: M Vehicles
A45: Zone Assignment Statistics
A46: Zone | B46: Shift | C46: Day 1 | D46: Day 2 | E46: Day 3 | F46: Day 4 | G46: Day 5 | H46: Day 6 | I46: Day 7 | J46: Day 8 | K46: Day 9 | L46: Day 10 | M46: Day 11 | N46: Day 12 | O46: Day 13 | P46: Day 14 | Q46: Day 15 | R46: Day 16 | S46: Day 17 | T46: Day 18 | U46: Day 19 | V46: Day 20 | W46: Day 21 | X46: Day 22 | Y46: Day 23 | Z46: Day 24 | AA46: Day 25 | AB46: Day 26 | AC46: Day 27 | AD46: Day 28 | AE46: Day 29 | AF46: Day 30 | AG46: Day 31
A47: Cargo | B47: M | C47: =IF(COUNTIF(C$3:C$21,$B47&" "&$A47)>=Description!C3,"Passed", "Failed") | D47: =IF(COUNTIF(D$3:D$21,$B47&" "&$A47)>=Description!D3,"Passed", "Failed") | E47: =IF(COUNTIF(E$3:E$21,$B47&" "&$A47)>=Description!E3,"Passed", "Failed") | F47: =IF(COUNTIF(F$3:F$21,$B47&" "&$A47)>=Description!F3,"Passed", "Failed") | G47: =IF(COUNTIF(G$3:G$21,$B47&" "&$A47)>=Description!G3,"Passed", "Failed") | H47: =IF(COUNTIF(H$3:H$21,$B47&" "&$A47)>=Description!H3,"Passed", "Failed") | I47: =IF(COUNTIF(I$3:I$21,$B47&" "&$A47)>=Description!I3,"Passed", "Failed") | J47: =IF(COUNTIF(J$3:J$21,$B47&" "&$A47)>=Description!J3,"Passed", "Failed") | ... AG47: =IF(COUNTIF(AG$3:AG$21,$B47&" "&$A47)>=Description!AG3,"Passed", "Failed")
A48: Cargo | B48: A | C48: =IF(COUNTIF(C$3:C$21,$B48&" "&$A48)>=Description!C4,"Passed", "Failed") | D48: =IF(COUNTIF(D$3:D$21,$B48&" "&$A48)>=Description!D4,"Passed", "Failed") | E48: =IF(COUNTIF(E$3:E$21,$B48&" "&$A48)>=Description!E4,"Passed", "Failed") | F48: =IF(COUNTIF(F$3:F$21,$B48&" "&$A48)>=Description!F4,"Passed", "Failed") | G48: =IF(COUNTIF(G$3:G$21,$B48&" "&$A48)>=Description!G4,"Passed", "Failed") | H48: =IF(COUNTIF(H$3:H$21,$B48&" "&$A48)>=Description!H4,"Passed", "Failed") | I48: =IF(COUNTIF(I$3:I$21,$B48&" "&$A48)>=Description!I4,"Passed", "Failed") | J48: =IF(COUNTIF(J$3:J$21,$B48&" "&$A48)>=Description!J4,"Passed", "Failed") | ... AG48: =IF(COUNTIF(AG$3:AG$21,$B48&" "&$A48)>=Description!AG4,"Passed", "Failed")
A49: Cargo | B49: N | C49: =IF(COUNTIF(C$3:C$21,$B49&" "&$A49)>=Description!C5,"Passed", "Failed") | D49: =IF(COUNTIF(D$3:D$21,$B49&" "&$A49)>=Description!D5,"Passed", "Failed") | E49: =IF(COUNTIF(E$3:E$21,$B49&" "&$A49)>=Description!E5,"Passed", "Failed") | F49: =IF(COUNTIF(F$3:F$21,$B49&" "&$A49)>=Description!F5,"Passed", "Failed") | G49: =IF(COUNTIF(G$3:G$21,$B49&" "&$A49)>=Description!G5,"Passed", "Failed") | H49: =IF(COUNTIF(H$3:H$21,$B49&" "&$A49)>=Description!H5,"Passed", "Failed") | I49: =IF(COUNTIF(I$3:I$21,$B49&" "&$A49)>=Description!I5,"Passed", "Failed") | J49: =IF(COUNTIF(J$3:J$21,$B49&" "&$A49)>=Description!J5,"Passed", "Failed") | ... AG49: =IF(COUNTIF(AG$3:AG$21,$B49&" "&$A49)>=Description!AG5,"Passed", "Failed")
A50: Pax | B50: M | C50: =IF(COUNTIF(C$3:C$21,$B50&" "&$A50)>=Description!C6,"Passed", "Failed") | D50: =IF(COUNTIF(D$3:D$21,$B50&" "&$A50)>=Description!D6,"Passed", "Failed") | E50: =IF(COUNTIF(E$3:E$21,$B50&" "&$A50)>=Description!E6,"Passed", "Failed") | F50: =IF(COUNTIF(F$3:F$21,$B50&" "&$A50)>=Description!F6,"Passed", "Failed") | G50: =IF(COUNTIF(G$3:G$21,$B50&" "&$A50)>=Description!G6,"Passed", "Failed") | H50: =IF(COUNTIF(H$3:H$21,$B50&" "&$A50)>=Description!H6,"Passed", "Failed") | I50: =IF(COUNTIF(I$3:I$21,$B50&" "&$A50)>=Description!I6,"Passed", "Failed") | J50: =IF(COUNTIF(J$3:J$21,$B50&" "&$A50)>=Description!J6,"Passed", "Failed") | ... AG50: =IF(COUNTIF(AG$3:AG$21,$B50&" "&$A50)>=Description!AG6,"Passed", "Failed")
A51: Pax | B51: A | C51: =IF(COUNTIF(C$3:C$21,$B51&" "&$A51)>=Description!C7,"Passed", "Failed") | D51: =IF(COUNTIF(D$3:D$21,$B51&" "&$A51)>=Description!D7,"Passed", "Failed") | E51: =IF(COUNTIF(E$3:E$21,$B51&" "&$A51)>=Description!E7,"Passed", "Failed") | F51: =IF(COUNTIF(F$3:F$21,$B51&" "&$A51)>=Description!F7,"Passed", "Failed") | G51: =IF(COUNTIF(G$3:G$21,$B51&" "&$A51)>=Description!G7,"Passed", "Failed") | H51: =IF(COUNTIF(H$3:H$21,$B51&" "&$A51)>=Description!H7,"Passed", "Failed") | I51: =IF(COUNTIF(I$3:I$21,$B51&" "&$A51)>=Description!I7,"Passed", "Failed") | J51: =IF(COUNTIF(J$3:J$21,$B51&" "&$A51)>=Description!J7,"Passed", "Failed") | ... AG51: =IF(COUNTIF(AG$3:AG$21,$B51&" "&$A51)>=Description!AG7,"Passed", "Failed")
A52: Pax | B52: N | C52: =IF(COUNTIF(C$3:C$21,$B52&" "&$A52)>=Description!C8,"Passed", "Failed") | D52: =IF(COUNTIF(D$3:D$21,$B52&" "&$A52)>=Description!D8,"Passed", "Failed") | E52: =IF(COUNTIF(E$3:E$21,$B52&" "&$A52)>=Description!E8,"Passed", "Failed") | F52: =IF(COUNTIF(F$3:F$21,$B52&" "&$A52)>=Description!F8,"Passed", "Failed") | G52: =IF(COUNTIF(G$3:G$21,$B52&" "&$A52)>=Description!G8,"Passed", "Failed") | H52: =IF(COUNTIF(H$3:H$21,$B52&" "&$A52)>=Description!H8,"Passed", "Failed") | I52: =IF(COUNTIF(I$3:I$21,$B52&" "&$A52)>=Description!I8,"Passed", "Failed") | J52: =IF(COUNTIF(J$3:J$21,$B52&" "&$A52)>=Description!J8,"Passed", "Failed") | ... AG52: =IF(COUNTIF(AG$3:AG$21,$B52&" "&$A52)>=Description!AG8,"Passed", "Failed")
A53: Vehicles | B53: M | C53: =IF(COUNTIF(C$3:C$21,$B53&" "&$A53)>=Description!C9,"Passed", "Failed") | D53: =IF(COUNTIF(D$3:D$21,$B53&" "&$A53)>=Description!D9,"Passed", "Failed") | E53: =IF(COUNTIF(E$3:E$21,$B53&" "&$A53)>=Description!E9,"Passed", "Failed") | F53: =IF(COUNTIF(F$3:F$21,$B53&" "&$A53)>=Description!F9,"Passed", "Failed") | G53: =IF(COUNTIF(G$3:G$21,$B53&" "&$A53)>=Description!G9,"Passed", "Failed") | H53: =IF(COUNTIF(H$3:H$21,$B53&" "&$A53)>=Description!H9,"Passed", "Failed") | I53: =IF(COUNTIF(I$3:I$21,$B53&" "&$A53)>=Description!I9,"Passed", "Failed") | J53: =IF(COUNTIF(J$3:J$21,$B53&" "&$A53)>=Description!J9,"Passed", "Failed") | ... AG53: =IF(COUNTIF(AG$3:AG$21,$B53&" "&$A53)>=Description!AG9,"Passed", "Failed")
A54: Vehicles | B54: A | C54: =IF(COUNTIF(C$3:C$21,$B54&" "&$A54)>=Description!C10,"Passed", "Failed") | D54: =IF(COUNTIF(D$3:D$21,$B54&" "&$A54)>=Description!D10,"Passed", "Failed") | E54: =IF(COUNTIF(E$3:E$21,$B54&" "&$A54)>=Description!E10,"Passed", "Failed") | F54: =IF(COUNTIF(F$3:F$21,$B54&" "&$A54)>=Description!F10,"Passed", "Failed") | G54: =IF(COUNTIF(G$3:G$21,$B54&" "&$A54)>=Description!G10,"Passed", "Failed") | H54: =IF(COUNTIF(H$3:H$21,$B54&" "&$A54)>=Description!H10,"Passed", "Failed") | I54: =IF(COUNTIF(I$3:I$21,$B54&" "&$A54)>=Description!I10,"Passed", "Failed") | J54: =IF(COUNTIF(J$3:J$21,$B54&" "&$A54)>=Description!J10,"Passed", "Failed") | ... AG54: =IF(COUNTIF(AG$3:AG$21,$B54&" "&$A54)>=Description!AG10,"Passed", "Failed")
...
